Workbook
Name CC_1: 'Contribution d''entretien'!$C$46
Name CC_2: 'Contribution d''entretien'!$D$46
Name man: 'Contribution d''entretien'!$F$45
Name nb_enfants: 'Contribution d''entretien'!$G$52
Name P_1: 'Contribution d''entretien'!$C$39
Name P_2: 'Contribution d''entretien'!$D$39

Sheet Contribution d'entretien
B2: Revenus
C4: Parent 1 | D4: Parent 2
B5: Revenus | C5: 5000 | D5: 4000
B6: Treizième salaire | C6: 0 | D6: 0
B7: Bonus annuel | C7: 0 | D7: 0
B8: Allocation(s) complémentaire(s) | C8: 0 | D8: 0
B9: Revenus complémentaires | C9: 0 | D9: 0
B10: TOTAL | C10: =SUM(C5*12+C6+C7)/12+SUM(C8:C9) -> 5000 | D10: =SUM(D5*12+D6+D7)/12+SUM(D8:D9) -> 4000
B12: Charges
B14: Montant de base | C14: 1200 | D14: 1350
B15: Part au loyer / intérêts hypothécaires | C15: 2500 | D15: 2000
B16: Coûts effectifs logement | C16: =IF(nb_enfants=0,C15,IF(P_1>=30%,IF(nb_enfants=1,C15*(1-Paramètres!$C8),IF(nb_enfants=2,(C15*(1-Paramètres!$D8)),IF(nb_enfants=3,(C15*(1-Paramètres!$E8)),C15*(1-Paramètres!$F8)))),C15)) -> 2500 | D16: =IF(nb_enfants=0,D15,IF(P_2>=30%,IF(nb_enfants=1,D15*(1-Paramètres!$C8),IF(nb_enfants=2,(D15*(1-Paramètres!$D8)),IF(nb_enfants=3,(D15*(1-Paramètres!$E8)),D15*(1-Paramètres!$F8)))),D15)) -> 2000
B17: Frais de chauffage | C17: 0 | D17: 0
B18: Frais accessoires | C18: 0 | D18: 0
B19: Prime LaMal/autres assurances obligatoires | C19: 545.95 | D19: 587.35
B20: Frais médicaux | D20: 0
B21: Frais de déplacement | C21: 284 | D21: 0
B22: Frais de repas | C22: 83 | D22: 0
B23: Leasing voiture si nécessaire | C23: 580.25 | D23: 385.95
B24: Autres charges
B25: TOTAL charges I | C25: =C14+SUM(C16:C24) -> 5193.2 | D25: =D14+SUM(D16:D24) -> 4323.3
B26: Impôts | C26: 1000 | D26: 200
B27: LCA | C27: 129 | D27: 160.7
B28: Autres assurances | C28: 31.4 | D28: 31
B29: Forfaits télécommunication | C29: 69 | D29: 78
B30: Caution loyer | C30: 17 | D30: 100
B31: Taxe déchets | C31: 0 | D31: 0
B32: 3ème pilier | C32: 250 | D32: 0
B33: Autres charges
B34: TOTAL charges I + II | C34: =SUM(C25:C33) -> 6689.6 | D34: =SUM(D25:D33) -> 4893
B37: Répartition garde
B39: % | C39: 0 | D39: =1-C39 -> 1
B41: Disponible
B43: Après déduction des charges I | C43: =C10-C25 -> -193.2 | D43: =D10-D25 -> -323.3
B44: Après déduction des charges I + II | C44: =C10-C34 -> -1689.6 | D44: =D10-D34 -> -893
B45: Disponible retenu | C45: =IF(man=1,C43,IF(man=2,C44,IF(OR($C44<0,$D44<0),C43,C44))) -> -193.2 | D45: =IF(man=1,D43,IF(man=2,D44,IF(OR($C44<0,$D44<0),D43,D44))) -> -323.3 | E45: Force manuellement disponible retenu 1 ou 2 | F45: 1 | G45: 0 ou vide:auto 1:dispo1 2:dispo2
B46: Pourcentage du disponible de la famille | C46: =IF(C45<=0,0,IF($C45*$D45>0,C45*100/($C45+$D45),100))/100 -> 0 | D46: =IF(D45<=0,0,IF($C45*$D45>0,D45*100/($C45+$D45),100))/100 -> 0
B47: Participation coûts directs enfants | C47: =IF(nb_enfants=0,0,SUM(C81:F81)) -> 0 | D47: =IF(nb_enfants=0,0,SUM(C82:F82)) -> 0
B48: Disponible après paiement des frais des enfants | C48: =C45-C47 -> -193.2 | D48: =D45-D47 -> -323.3 | E48: Si Disponible négatif du parent non-gardien, adapter les charges
C51: Frais des enfants | G51: Nombre enfants
...

Sheet Récapitulatif
B4: Parent 1 | C4: Parent 2
A5: TOTAL revenus | B5: ='Contribution d''entretien'!C10 -> 5000 | C5: ='Contribution d''entretien'!D10 -> 4000
A6: Charges | B6: ='Contribution d''entretien'!C34 -> 6689.6 | C6: ='Contribution d''entretien'!D34 -> 4893
A7: Couts direct | B7: ='Contribution d''entretien'!C47 -> 0 | C7: ='Contribution d''entretien'!D47 -> 0
A8: Participation dispo | B8: =SUM('Contribution d''entretien'!C83:E83) -> 0 | C8: =SUM('Contribution d''entretien'!C84:E84) -> 0
A11: Reste | B11: =B5-SUM(B6:B10) -> -1689.6 | C11: =C5-SUM(C6:C10) -> -893

Sheet Paramètres
A7: Nb enfants | B7: 0 | C7: 1 | D7: 2 | E7: 3 | F7: 4
A8: Part au loyer enfants | B8: 0 | C8: 0.15 | D8: 0.3 | E8: 0.35 | F8: 0.4
